2025-10-05 20:47:33 ERROR 400 response executing GraphQL.
2025-10-05 20:47:33 ERROR {"errors":[{"message":"Invalid sweep config: invalid hyperparameter configuration: lr","path":["upsertSweep"]}],"data":{"upsertSweep":null}}
2025-10-05 20:47:33 ERROR Traceback (most recent call last):
  File "/root/miniconda3/lib/python3.12/site-packages/wandb/sdk/lib/retry.py", line 131, in __call__
    result = self._call_fn(*args, **kwargs)
             ^^^^^^^^^^^^^^^^^^^^^^^^^^^^^^
  File "/root/miniconda3/lib/python3.12/site-packages/wandb/sdk/internal/internal_api.py", line 354, in execute
    return self.client.execute(*args, **kwargs)  # type: ignore
           ^^^^^^^^^^^^^^^^^^^^^^^^^^^^^^^^^^^^
  File "/root/miniconda3/lib/python3.12/site-packages/wandb/vendor/gql-0.2.0/wandb_gql/client.py", line 52, in execute
    result = self._get_result(document, *args, **kwargs)
             ^^^^^^^^^^^^^^^^^^^^^^^^^^^^^^^^^^^^^^^^^^^
  File "/root/miniconda3/lib/python3.12/site-packages/wandb/vendor/gql-0.2.0/wandb_gql/client.py", line 60, in _get_result
    return self.transport.execute(document, *args, **kwargs)
           ^^^^^^^^^^^^^^^^^^^^^^^^^^^^^^^^^^^^^^^^^^^^^^^^^
  File "/root/miniconda3/lib/python3.12/site-packages/wandb/sdk/lib/gql_request.py", line 59, in execute
    request.raise_for_status()
  File "/root/miniconda3/lib/python3.12/site-packages/requests/models.py", line 1024, in raise_for_status
    raise HTTPError(http_error_msg, response=self)
requests.exceptions.HTTPError: 400 Client Error: Bad Request for url: https://api.wandb.ai/graphql

During handling of the above exception, another exception occurred:

Traceback (most recent call last):
  File "/root/miniconda3/lib/python3.12/site-packages/wandb/cli/cli.py", line 103, in wrapper
    return func(*args, **kwargs)
           ^^^^^^^^^^^^^^^^^^^^^
  File "/root/miniconda3/lib/python3.12/site-packages/wandb/cli/cli.py", line 886, in sweep
    sweep_id, warnings = api.upsert_sweep(
                         ^^^^^^^^^^^^^^^^^
  File "/root/miniconda3/lib/python3.12/site-packages/wandb/apis/internal.py", line 133, in upsert_sweep
    return self.api.upsert_sweep(*args, **kwargs)
           ^^^^^^^^^^^^^^^^^^^^^^^^^^^^^^^^^^^^^^
  File "/root/miniconda3/lib/python3.12/site-packages/wandb/apis/normalize.py", line 73, in wrapper
    raise err
  File "/root/miniconda3/lib/python3.12/site-packages/wandb/apis/normalize.py", line 41, in wrapper
    return func(*args, **kwargs)
           ^^^^^^^^^^^^^^^^^^^^^
  File "/root/miniconda3/lib/python3.12/site-packages/wandb/sdk/internal/internal_api.py", line 3294, in upsert_sweep
    raise e
  File "/root/miniconda3/lib/python3.12/site-packages/wandb/sdk/internal/internal_api.py", line 3288, in upsert_sweep
    response = self.gql(
               ^^^^^^^^^
  File "/root/miniconda3/lib/python3.12/site-packages/wandb/sdk/internal/internal_api.py", line 326, in gql
    ret = self._retry_gql(
          ^^^^^^^^^^^^^^^^
  File "/root/miniconda3/lib/python3.12/site-packages/wandb/sdk/lib/retry.py", line 147, in __call__
    retry_timedelta_triggered = check_retry_fn(e)
                                ^^^^^^^^^^^^^^^^^
  File "/root/miniconda3/lib/python3.12/site-packages/wandb/util.py", line 881, in no_retry_4xx
    raise UsageError(body["errors"][0]["message"])
wandb.errors.errors.UsageError: Invalid sweep config: invalid hyperparameter configuration: lr

2025-10-05 23:26:21 ERROR Traceback (most recent call last):
  File "/root/miniconda3/lib/python3.12/site-packages/wandb/apis/normalize.py", line 41, in wrapper
    return func(*args, **kwargs)
           ^^^^^^^^^^^^^^^^^^^^^
  File "/root/miniconda3/lib/python3.12/site-packages/wandb/sdk/internal/internal_api.py", line 3259, in upsert_sweep
    config = self._validate_config_and_fill_distribution(config)
             ^^^^^^^^^^^^^^^^^^^^^^^^^^^^^^^^^^^^^^^^^^^^^^^^^^^
  File "/root/miniconda3/lib/python3.12/site-packages/wandb/sdk/internal/internal_api.py", line 3129, in _validate_config_and_fill_distribution
    if "min" in parameter and "max" in parameter:
       ^^^^^^^^^^^^^^^^^^
TypeError: argument of type 'float' is not iterable

During handling of the above exception, another exception occurred:

Traceback (most recent call last):
  File "/root/miniconda3/lib/python3.12/site-packages/wandb/cli/cli.py", line 103, in wrapper
    return func(*args, **kwargs)
           ^^^^^^^^^^^^^^^^^^^^^
  File "/root/miniconda3/lib/python3.12/site-packages/wandb/cli/cli.py", line 886, in sweep
    sweep_id, warnings = api.upsert_sweep(
                         ^^^^^^^^^^^^^^^^^
  File "/root/miniconda3/lib/python3.12/site-packages/wandb/apis/internal.py", line 133, in upsert_sweep
    return self.api.upsert_sweep(*args, **kwargs)
           ^^^^^^^^^^^^^^^^^^^^^^^^^^^^^^^^^^^^^^
  File "/root/miniconda3/lib/python3.12/site-packages/wandb/apis/normalize.py", line 87, in wrapper
    raise CommError(message, err).with_traceback(sys.exc_info()[2])
  File "/root/miniconda3/lib/python3.12/site-packages/wandb/apis/normalize.py", line 41, in wrapper
    return func(*args, **kwargs)
           ^^^^^^^^^^^^^^^^^^^^^
  File "/root/miniconda3/lib/python3.12/site-packages/wandb/sdk/internal/internal_api.py", line 3259, in upsert_sweep
    config = self._validate_config_and_fill_distribution(config)
             ^^^^^^^^^^^^^^^^^^^^^^^^^^^^^^^^^^^^^^^^^^^^^^^^^^^
  File "/root/miniconda3/lib/python3.12/site-packages/wandb/sdk/internal/internal_api.py", line 3129, in _validate_config_and_fill_distribution
    if "min" in parameter and "max" in parameter:
       ^^^^^^^^^^^^^^^^^^
wandb.errors.errors.CommError: argument of type 'float' is not iterable

